Workbook

Sheet README
A1: San Francisco Housing Stock & Development Activity — Data Workbook
A2: Compiled 2026-09-09 by Claude for Paul (RaaP). All figures trace to a source row in the Sources tab; every Projects row carries its own source URL.
A4: Tabs
A5: Summary — live COUNTIFS/SUMIFS over the Projects tab, plus the official citywide figures (Housing Inventory 2025, Pipeline Report 2026 Q2).
A6: Stock — citywide housing stock by building type (2024, 2025), 41 Analysis Neighborhoods (2025), tenure / vacancy / age of stock (ACS).
A7: Trend — units authorized, completed, demolished, altered, net change, 2006–2025 + 2026 H1; affordable production by income level and source, 2021–2025.
A8: Pipeline_Q2_2026 — SF Planning Pipeline Report snapshot by stage and the 14 major multi-phase projects.
A9: Projects — one row per project (265 rows): completions 2023–2026 YTD (10+ units), under construction, permitted, approved, filed/pre-development, and multi-phase remainders. Capital-stack columns populated where public sources exist; otherwise blank.
A10: Sources — every dataset/report used, with URL and retrieval date.
A11: How_to_update — refresh steps and cadence per source.
A13: Status (normalized) definitions
A14: Complete = TCO or CFC issued (Housing Inventory counts TCO as complete).
... A27: Yellow cells = analyst estimate or placeholder to verify.

Sheet Summary
A1: San Francisco housing — summary dashboard
A2: Formulas recalc from the Projects tab; 'official' blocks are hard-coded from SF Planning reports (see Sources).
A4: A. Official citywide figures
A5: Metric | B5: Value | C5: As of | D5: Source
A6: Total housing units (SF Planning) | B6: 422958 | C6: Dec 31, 2025 | D6: Housing Inventory 2025, Table 1
A7: Net units added 2025 | B7: 2669 | C7: 2025 | D7: HI 2025, Table 2
A8: Units completed from new construction 2025 | B8: 2406 | C8: 2025 | D8: HI 2025, Table 2
A9: Units completed 2026 H1 (ready for occupancy) | B9: 405 | C9: Jan–Jun 2026 | D9: The Frisc (SF Planning Housing Dashboard), Jul 2026
A10: Net units authorized for construction 2025 | B10: 1900 | C10: 2025 | D10: HI 2025, Table 2
A11: Units approved by Planning 2025 | B11: 3723 | C11: 2025 | D11: HI 2025, Table 3
A12: Units filed at Planning 2025 | B12: 9614 | C12: 2025 | D12: HI 2025, Table 3
A13: New affordable units completed 2025 | B13: 1758 | C13: 2025 | D13: HI 2025, Table 23 (66% of new units)
A14: Pipeline — total new units | B14: 75853 | C14: Q2 2026 (Apr 2026) | D14: Pipeline Report 2026 Q2
A15: Pipeline — affordable units (24%) | B15: 18536 | C15: Q2 2026 | D15: Pipeline Report 2026 Q2
A16: Pipeline — under construction | B16: 3301 | C16: Q2 2026 | D16: Pipeline Report 2026 Q2
A17: Pipeline — building permits issued (site) | B17: 1219 | C17: Q2 2026 | D17: Pipeline Report 2026 Q2
... A24: RHNA 2023–2031 progress (units credited) | B24: 9581 | C24: Dec 2025 | D24: HI 2025 (12% of 82,069)
A26: B. Projects tracked in this workbook — by normalized status
A27: Status (normalized) | B27: Projects | C27: Total units | D27: Affordable units | E27: Share of tracked units
A28: Complete | B28: =COUNTIFS(Projects!$G:$G,A28) -> 44 | C28: =SUMIFS(Projects!$J:$J,Projects!$G:$G,A28) -> 6022 | D28: =SUMIFS(Projects!$K:$K,Projects!$G:$G,A28) -> 3142 | E28: =IF(C34=0,0,C28/C34) -> 0.065794793
A29: Under Construction | B29: =COUNTIFS(Projects!$G:$G,A29) -> 35 | C29: =SUMIFS(Projects!$J:$J,Projects!$G:$G,A29) -> 3544 | D29: =SUMIFS(Projects!$K:$K,Projects!$G:$G,A29) -> 2555 | E29: =IF(C34=0,0,C29/C34) -> 0.038720815
A30: Permitted | B30: =COUNTIFS(Projects!$G:$G,A30) -> 36 | C30: =SUMIFS(Projects!$J:$J,Projects!$G:$G,A30) -> 3127 | D30: =SUMIFS(Projects!$K:$K,Projects!$G:$G,A30) -> 1135 | E30: =IF(C34=0,0,C30/C34) -> 0.034164782
A31: Approved | B31: =COUNTIFS(Projects!$G:$G,A31) -> 100 | C31: =SUMIFS(Projects!$J:$J,Projects!$G:$G,A31) -> 29126 | D31: =SUMIFS(Projects!$K:$K,Projects!$G:$G,A31) -> 4375 | E31: =IF(C34=0,0,C31/C34) -> 0.31822304
A32: Under Review | B32: =COUNTIFS(Projects!$G:$G,A32) -> 36 | C32: =SUMIFS(Projects!$J:$J,Projects!$G:$G,A32) -> 9229 | D32: =SUMIFS(Projects!$K:$K,Projects!$G:$G,A32) -> 3656 | E32: =IF(C34=0,0,C32/C34) -> 0.10083363
A33: Major Multi-Phase (remaining) | B33: =COUNTIFS(Projects!$G:$G,A33) -> 14 | C33: =SUMIFS(Projects!$J:$J,Projects!$G:$G,A33) -> 40479 | D33: =SUMIFS(Projects!$K:$K,Projects!$G:$G,A33) -> 0 | E33: =IF(C34=0,0,C33/C34) -> 0.44226294
A34: Total | B34: =SUM(B28:B33) -> 265 | C34: =SUM(C28:C33) -> 91527 | D34: =SUM(D28:D33) -> 14863 | E34: 1
A35: Note: 'Complete' here = projects ≥10 units completed 2023–2026 YTD only (not all-time). Multi-phase remainders are unit counts from the Pipeline Report, not project rows with detail.
A37: C. Units by size bucket × status (SUMIFS on Projects)
A38: Size bucket (total units) | B38: Complete | C38: Under Construction | D38: Permitted | E38: Approved | F38: Under Review | G38: Major Multi-Phase (remaining) | H38: All
A39: ≤4 | B39: =SUMIFS(Projects!$J:$J,Projects!$M:$M,$A39,Projects!$G:$G,"Complete") -> 0 | C39: =SUMIFS(Projects!$J:$J,Projects!$M:$M,$A39,Projects!$G:$G,"Under Construction") -> 0 | D39: =SUMIFS(Projects!$J:$J,Projects!$M:$M,$A39,Projects!$G:$G,"Permitted") -> 0 | E39: =SUMIFS(Projects!$J:$J,Projects!$M:$M,$A39,Projects!$G:$G,"Approved") -> 0 | F39: =SUMIFS(Projects!$J:$J,Projects!$M:$M,$A39,Projects!$G:$G,"Under Review") -> 0 | G39: =SUMIFS(Projects!$J:$J,Projects!$M:$M,$A39,Projects!$G:$G,"Major Multi-Phase (remaining)") -> 0 | H39: =SUM(B39:G39) -> 0
A40: 5–10 | B40: =SUMIFS(Projects!$J:$J,Projects!$M:$M,$A40,Projects!$G:$G,"Complete") -> 0 | C40: =SUMIFS(Projects!$J:$J,Projects!$M:$M,$A40,Projects!$G:$G,"Under Construction") -> 0 | D40: =SUMIFS(Projects!$J:$J,Projects!$M:$M,$A40,Projects!$G:$G,"Permitted") -> 18 | E40: =SUMIFS(Projects!$J:$J,Projects!$M:$M,$A40,Projects!$G:$G,"Approved") -> 0 | F40: =SUMIFS(Projects!$J:$J,Projects!$M:$M,$A40,Projects!$G:$G,"Under Review") -> 5 | G40: =SUMIFS(Projects!$J:$J,Projects!$M:$M,$A40,Projects!$G:$G,"Major Multi-Phase (remaining)") -> 0 | H40: =SUM(B40:G40) -> 23
A41: 11–20 | B41: =SUMIFS(Projects!$J:$J,Projects!$M:$M,$A41,Projects!$G:$G,"Complete") -> 46 | C41: =SUMIFS(Projects!$J:$J,Projects!$M:$M,$A41,Projects!$G:$G,"Under Construction") -> 20 | D41: =SUMIFS(Projects!$J:$J,Projects!$M:$M,$A41,Projects!$G:$G,"Permitted") -> 86 | E41: =SUMIFS(Projects!$J:$J,Projects!$M:$M,$A41,Projects!$G:$G,"Approved") -> 162 | F41: =SUMIFS(Projects!$J:$J,Projects!$M:$M,$A41,Projects!$G:$G,"Under Review") -> 0 | G41: =SUMIFS(Projects!$J:$J,Projects!$M:$M,$A41,Projects!$G:$G,"Major Multi-Phase (remaining)") -> 0 | H41: =SUM(B41:G41) -> 314
A42: 21–50 | B42: =SUMIFS(Projects!$J:$J,Projects!$M:$M,$A42,Projects!$G:$G,"Complete") -> 246 | C42: =SUMIFS(Projects!$J:$J,Projects!$M:$M,$A42,Projects!$G:$G,"Under Construction") -> 232 | D42: =SUMIFS(Projects!$J:$J,Projects!$M:$M,$A42,Projects!$G:$G,"Permitted") -> 329 | E42: =SUMIFS(Projects!$J:$J,Projects!$M:$M,$A42,Projects!$G:$G,"Approved") -> 838 | F42: =SUMIFS(Projects!$J:$J,Projects!$M:$M,$A42,Projects!$G:$G,"Under Review") -> 131 | G42: =SUMIFS(Projects!$J:$J,Projects!$M:$M,$A42,Projects!$G:$G,"Major Multi-Phase (remaining)") -> 0 | H42: =SUM(B42:G42) -> 1776
A43: 51–250 | B43: =SUMIFS(Projects!$J:$J,Projects!$M:$M,$A43,Projects!$G:$G,"Complete") -> 3644 | C43: =SUMIFS(Projects!$J:$J,Projects!$M:$M,$A43,Projects!$G:$G,"Under Construction") -> 2564 | D43: =SUMIFS(Projects!$J:$J,Projects!$M:$M,$A43,Projects!$G:$G,"Permitted") -> 1541 | E43: =SUMIFS(Projects!$J:$J,Projects!$M:$M,$A43,Projects!$G:$G,"Approved") -> 5471 | F43: =SUMIFS(Projects!$J:$J,Projects!$M:$M,$A43,Projects!$G:$G,"Under Review") -> 2642 | G43: =SUMIFS(Projects!$J:$J,Projects!$M:$M,$A43,Projects!$G:$G,"Major Multi-Phase (remaining)") -> 0 | H43: =SUM(B43:G43) -> 15862
A44: 251+ | B44: =SUMIFS(Projects!$J:$J,Projects!$M:$M,$A44,Projects!$G:$G,"Complete") -> 2086 | C44: =SUMIFS(Projects!$J:$J,Projects!$M:$M,$A44,Projects!$G:$G,"Under Construction") -> 728 | D44: =SUMIFS(Projects!$J:$J,Projects!$M:$M,$A44,Projects!$G:$G,"Permitted") -> 1153 | E44: =SUMIFS(Projects!$J:$J,Projects!$M:$M,$A44,Projects!$G:$G,"Approved") -> 22655 | F44: =SUMIFS(Projects!$J:$J,Projects!$M:$M,$A44,Projects!$G:$G,"Under Review") -> 6451 | G44: =SUMIFS(Projects!$J:$J,Projects!$M:$M,$A44,Projects!$G:$G,"Major Multi-Phase (remaining)") -> 40479 | H44: =SUM(B44:G44) -> 73552
A45: All buckets | B45: =SUM(B39:B44) -> 6022 | C45: =SUM(C39:C44) -> 3544 | D45: =SUM(D39:D44) -> 3127 | E45: =SUM(E39:E44) -> 29126 | F45: =SUM(F39:F44) -> 9229 | G45: =SUM(G39:G44) -> 40479 | H45: =SUM(H39:H44) -> 91527
A47: D. Project count by size bucket × status (COUNTIFS on Projects)
A48: Size bucket (total units) | B48: Complete | C48: Under Construction | D48: Permitted | E48: Approved | F48: Under Review | G48: Major Multi-Phase (remaining) | H48: All
A49: ≤4 | B49: =COUNTIFS(Projects!$M:$M,$A49,Projects!$G:$G,"Complete") -> 0 | C49: =COUNTIFS(Projects!$M:$M,$A49,Projects!$G:$G,"Under Construction") -> 0 | D49: =COUNTIFS(Projects!$M:$M,$A49,Projects!$G:$G,"Permitted") -> 0 | E49: =COUNTIFS(Projects!$M:$M,$A49,Projects!$G:$G,"Approved") -> 0 | F49: =COUNTIFS(Projects!$M:$M,$A49,Projects!$G:$G,"Under Review") -> 0 | G49: =COUNTIFS(Projects!$M:$M,$A49,Projects!$G:$G,"Major Multi-Phase (remaining)") -> 0 | H49: =SUM(B49:G49) -> 0
A50: 5–10 | B50: =COUNTIFS(Projects!$M:$M,$A50,Projects!$G:$G,"Complete") -> 0 | C50: =COUNTIFS(Projects!$M:$M,$A50,Projects!$G:$G,"Under Construction") -> 0 | D50: =COUNTIFS(Projects!$M:$M,$A50,Projects!$G:$G,"Permitted") -> 2 | E50: =COUNTIFS(Projects!$M:$M,$A50,Projects!$G:$G,"Approved") -> 0 | F50: =COUNTIFS(Projects!$M:$M,$A50,Projects!$G:$G,"Under Review") -> 1 | G50: =COUNTIFS(Projects!$M:$M,$A50,Projects!$G:$G,"Major Multi-Phase (remaining)") -> 0 | H50: =SUM(B50:G50) -> 3
...

Sheet Stock
A1: Housing stock — citywide and by neighborhood
A3: A. Citywide housing stock by building type (SF Planning)
A4: Year-end | B4: Single family | C4: 2–4 units | D4: 5–9 units | E4: 10–19 units | F4: 20+ units | G4: Total | H4: Source
A5: 2024 (restated in HI 2025) | B5: 94500 | C5: 82988 | D5: 39740 | E5: 39649 | F5: 163412 | G5: 420289 | H5: HI 2025 Table 1
A6: 2025 net change | B6: 17 | C6: 155 | D6: 37 | E6: 67 | F6: 2393 | G6: 2669 | H6: HI 2025 Table 1
A7: 2025 | B7: 94517 | C7: 83143 | D7: 39777 | E7: 39716 | F7: 165805 | G7: 422958 | H7: HI 2025 Table 1
A8: 2024 (as published in HI 2024) | B8: 95071 | C8: 83015 | D8: 39321 | E8: 39064 | F8: 161353 | G8: 417824 | H8: HI 2024 Table 1 — superseded
A9: 2023 (as published in HI 2024) | B9: 95051 | C9: 82856 | D9: 39299 | E9: 39040 | F9: 159981 | G9: 416227 | H9: HI 2024 Table 1 — superseded
A10: Share of 2025 stock | B10: =B7/$G$7 -> 0.22346663 | C10: =C7/$G$7 -> 0.19657507 | D10: =D7/$G$7 -> 0.094044799 | E10: =E7/$G$7 -> 0.093900576 | F10: =F7/$G$7 -> 0.39201292
A11: Building-type split reset in the 2024 report (2020 Census baseline + ACS ratios). The 2023 report showed 122,816 single-family; later reports show ~95k. Use the latest report's series.
A13: B. Tenure, vacancy, age of stock (Census ACS / HUD)
A14: Metric | B14: Value | C14: Note | D14: Source
A15: Total housing inventory (HUD CMAR, SF submarket, current) | B15: 420800 | D15: HUD Comprehensive Housing Market Analysis, SF-Redwood City-SSF, 2024
A16: Occupied units | B16: 380400 | D16: HUD CMAR 2024
A17: Owner-occupied share | B17: 32.6% | C17: of occupied units | D17: HUD CMAR 2024
A18: Renter-occupied share | B18: 67.4% | C18: of occupied units | D18: HUD CMAR 2024
A19: Vacant units (all categories) | B19: 40450 | C19: ≈9.6% of inventory; ACS 'vacant' includes seasonal, sold/rented-not-occupied, under repair | D19: HUD CMAR 2024
A20: Vacant — for rent share of vacant | B20: 26.5% | C20: ACS 5-yr | D20: Social Explorer / ACS 5-year (SF County)
A21: Vacant — for sale share of vacant | B21: 2.5% | C21: ACS 5-yr | D21: Social Explorer / ACS 5-year
A22: Median year structure built | B22: 1944 | D22: ACS 5-year (SF County)
A23: Built 1939 or earlier | B23: 45.4% | C23: of housing units | D23: ACS 5-year via NeighborhoodScout
A24: Built 1940–1969 | B24: 24.7% | D24: ACS 5-year via NeighborhoodScout
A25: Built 1970–1999 | B25: 16.3% | D25: ACS 5-year via NeighborhoodScout
A26: Built 2000 or later | B26: 13.6% | D26: ACS 5-year via NeighborhoodScout
A27: Single-unit structures share | B27: 30.9% | C27: ACS 5-yr; SF Planning building-type table above is the operative series | D27: ACS 5-year
A28: Multi-unit structures share | B28: 68.9% | D28: ACS 5-year
A29: Residential hotel (SRO) rooms | B29: 18997 | C29: 497 buildings (375 for-profit / 122 nonprofit) | D29: HI 2025 Table 20 (DBI)
A30: New condominiums recorded 2025 | B30: 2989 | C30: vs 813 in 2024 | D30: HI 2025 Table 16 (DPW)
A31: ADUs added or legalized 2025 | B31: 223 | C31: folded into totals above | D31: HI 2025 Table 9
A32: Refresh age/tenure from data.census.gov table DP04 (ACS 1-year, San Francisco County) — cadence: annually each September.
A34: C. Housing stock by Analysis Neighborhood, year-end 2025 (HI 2025 Table 28) + 2025 net gain (Table 27)
A35: Analysis Neighborhood | B35: Single family | C35: 2–4 units | D35: 5–9 units | E35: 10–19 units | F35: 20+ units | G35: Total 2025 | H35: Net gain 2025 | I35: New-construction units 2025
A36: Bayview Hunters Point | B36: 5846 | C36: 1458 | D36: 281 | E36: 296 | F36: 5735 | G36: 13616 | H36: 320 | I36: 304
A37: Bernal Heights | B37: 4674 | C37: 3234 | D37: 582 | E37: 253 | F37: 682 | G37: 9425 | H37: 156 | I37: 147
A38: Castro/Upper Market | B38: 1583 | C38: 5684 | D38: 2092 | E38: 1284 | F38: 1887 | G38: 12530 | H38: 10 | I38: 1
A39: Chinatown | B39: 27 | C39: 816 | D39: 1099 | E39: 889 | F39: 3230 | G39: 6061 | H39: 0 | I39: 0
A40: Excelsior | B40: 7688 | C40: 1163 | D40: 341 | E40: 282 | F40: 770 | G40: 10244 | H40: 7 | I40: 0
A41: Financial District/South Beach | B41: 7 | C41: 105 | D41: 110 | E41: 196 | F41: 19649 | G41: 20067 | H41: 158 | I41: 151
A42: Glen Park | B42: 1991 | C42: 973 | D42: 119 | E42: 116 | F42: 1040 | G42: 4239 | H42: 0 | I42: 0
A43: Golden Gate Park | B43: 0 | C43: 0 | D43: 0 | E43: 0 | F43: 42 | G43: 42 | H43: 0 | I43: 0
...

Sheet Trend
A1: Housing production trend, 2006–2026 H1 (SF Planning Housing Inventory 2025, Table 2)
A3: Year | B3: Net units authorized for construction | C3: Units completed from new construction | D3: Units demolished | E3: Units gained/lost from alterations | F3: Net change in units | G3: Source
A4: 2006 | B4: 4275 | C4: 1358 | D4: 45 | E4: 285 | F4: 1598 | G4: HI 2025 Table 2
A5: 2007 | B5: 3133 | C5: 2084 | D5: 37 | E5: 472 | F5: 2519 | G5: HI 2025 Table 2
A6: 2008 | B6: 2355 | C6: 2142 | D6: 60 | E6: 188 | F6: 2270 | G6: HI 2025 Table 2
A7: 2009 | B7: 288 | C7: 2639 | D7: 31 | E7: 469 | F7: 3077 | G7: HI 2025 Table 2
A8: 2010 | B8: 314 | C8: 2737 | D8: 56 | E8: 282 | F8: 2963 | G8: HI 2025 Table 2
A9: 2011 | B9: 2412 | C9: 809 | D9: 33 | E9: -7 | F9: 769 | G9: HI 2025 Table 2
A10: 2012 | B10: 2500 | C10: 289 | D10: 141 | E10: 345 | F10: 493 | G10: HI 2025 Table 2
A11: 2013 | B11: 3221 | C11: 1859 | D11: 431 | E11: 240 | F11: 1668 | G11: HI 2025 Table 2
A12: 2014 | B12: 5176 | C12: 2533 | D12: 95 | E12: 100 | F12: 2538 | G12: HI 2025 Table 2
A13: 2015 | B13: 3605 | C13: 2497 | D13: 26 | E13: 131 | F13: 2602 | G13: HI 2025 Table 2
A14: 2016 | B14: 2606 | C14: 2169 | D14: 23 | E14: 814 | F14: 2960 | G14: HI 2025 Table 2
A15: 2017 | B15: 4560 | C15: 4972 | D15: 24 | E15: 376 | F15: 5324 | G15: HI 2025 Table 2
... A23: 2025 | B23: 1900 | C23: 2406 | D23: 6 | E23: 269 | F23: 2669 | G23: HI 2025 Table 2
A24: 2026 H1 | C24: 405 | G24: SF Planning Housing Dashboard via The Frisc (Jul 2026); 'ready for occupancy'
A25: 10-yr avg 2016–2025 | B25: =AVERAGE(B14:B23) -> 2924.7 | C25: =AVERAGE(C14:C23) -> 3259.5 | D25: =AVERAGE(D14:D23) -> 85.2 | E25: =AVERAGE(E14:E23) -> 448 | F25: =AVERAGE(F14:F23) -> 3622.3
A27: New units added by building type, 2021–2025 (HI 2025 Table 13; includes ADUs and alterations)
A28: Year | B28: Single family | C28: 2–4 | D28: 5–9 | E28: 10–19 | F28: 20+ | G28: Total
A29: 2021 | B29: 26 | C29: 229 | D29: 114 | E29: 109 | F29: 4160 | G29: 4638
A30: 2022 | B30: 16 | C30: 211 | D30: 100 | E30: 59 | F30: 2495 | G30: 2881
A31: 2023 | B31: 32 | C31: 192 | D31: 81 | E31: 69 | F31: 2207 | G31: 2581
A32: 2024 | B32: 33 | C32: 166 | D32: 70 | E32: 97 | F32: 1375 | G32: 1741
A33: 2025 | B33: 26 | C33: 157 | D33: 37 | E33: 67 | F33: 2395 | G33: 2682
A35: New affordable units by income level, 2021–2025 (HI 2025 Table 23)
A36: Year | B36: Extremely Low (≤30% AMI) | C36: Very Low (≤50%) | D36: Low (≤80%) | E36: Moderate (≤120%) | F36: Moderate non-deed-restricted (ADUs) | G36: Total affordable | H36: Total all new units | I36: Affordable share
A37: 2021 | B37: 34 | C37: 529 | D37: 551 | E37: 98 | F37: 296 | G37: 1508 | H37: 4638 | I37: =G37/H37 -> 0.32514015
A38: 2022 | B38: 188 | C38: 461 | D38: 206 | E38: 70 | F38: 270 | G38: 1195 | H38: 2881 | I38: =G38/H38 -> 0.41478653
A39: 2023 | B39: 0 | C39: 209 | D39: 288 | E39: 212 | F39: 237 | G39: 946 | H39: 2581 | I39: =G39/H39 -> 0.3665246
A40: 2024 | B40: 100 | C40: 182 | D40: 327 | E40: 294 | F40: 212 | G40: 1115 | H40: 1741 | I40: =G40/H40 -> 0.64043653
A41: 2025 | B41: 216 | C41: 801 | D41: 495 | E41: 45 | F41: 201 | G41: 1758 | H41: 2682 | I41: =G41/H41 -> 0.65548098
A43: Affordable production by source, 2021–2025 (HI 2025 Table 24)
A44: Year | B44: Inclusionary units | C44: 100% affordable units | D44: ADU / legalizations | E44: Total
A45: 2021 | B45: 226 | C45: 986 | D45: 297 | E45: 1509
A46: 2022 | B46: 197 | C46: 728 | D46: 270 | E46: 1195
A47: 2023 | B47: 144 | C47: 585 | D47: 239 | E47: 968
A48: 2024 | B48: 83 | C48: 820 | D48: 212 | E48: 1115
A49: 2025 | B49: 117 | C49: 1440 | D49: 201 | E49: 1758
A51: Units authorized for construction by building type, 2021–2025 (HI 2025 Table 4)
A52: Year | B52: Single family | C52: 2–4 | D52: 5–9 | E52: 10–19 | F52: 20+ | G52: Total new units | H52: Projects
...

Sheet Pipeline_Q2_2026
A1: SF Planning Housing Development Pipeline — 2026 Q2 snapshot (projects and permits as of April 2026)
A3: Stage | B3: New pipeline units | C3: Share | D3: Definition
A4: Under Construction | B4: 3301 | C4: =B4/$B$11 -> 0.044079158 | D4: Issued full building permit, or site permit + approved first construction document
A5: Building Permits Issued (site permit) | B5: 1219 | C5: =B5/$B$11 -> 0.016277641 | D5: Site permit issued, no FCD yet; not counted toward RHNA
A6: Building Permits Approved | B6: 2422 | C6: =B6/$B$11 -> 0.03234163 | D6: Permit approved by DBI, not yet issued
A7: Building Permits Filed | B7: 7856 | C7: =B7/$B$11 -> 0.10490332 | D7: Includes estimated inclusionary units for projects that haven't declared method
A8: Building Permits Not Yet Filed (entitled) | B8: 9477 | C8: =B8/$B$11 -> 0.12654898 | D8: Planning approval granted; no building permit application
A9: Applications Filed (Under Review) | B9: 13036 | C9: =B9/$B$11 -> 0.17407328 | D9: Planning application filed; includes ministerial projects with BP filed
A10: Major Multi-Phased Projects (remaining) | B10: 37577 | C10: =B10/$B$11 -> 0.50177599 | D10: Entitled master plans; un-permitted phases only
A11: Total new pipeline units | B11: =SUM(B4:B10) -> 74888 | C11: 1
A12: New affordable units in pipeline | B12: 18536 | C12: =B12/B11 -> 0.24751629 | D12: Includes estimated inclusionary units; boosted by MOHCD Affordable Housing Pipeline data fill-in
A13: Source: https://sfplanning.org/project/pipeline-report (PDF: Housing_Production_Development_Pipeline-2026Q2.pdf). Under-construction units were 4,545 five years earlier; 'permits not yet filed' was 448 (The Frisc).
A15: Major multi-phase projects — remaining units (Pipeline Report 2026 Q2)
A16: Project | B16: Remaining units | C16: Master developer (per public sources)
A17: Candlestick Point / Hunters Point Shipyard | B17: 9637 | C17: FivePoint (Lennar)
A18: Treasure Island | B18: 6273 | C18: Treasure Island Community Development (Wilson Meany / Stockbridge / Lennar)
A19: Parkmerced | B19: 5314 | C19: Maximus Real Estate Partners
A20: Flower Mart (Central SoMa) | B20: 3532 | C20: Kilroy Realty
A21: Stonestown | B21: 3491 | C21: Brookfield Properties
A22: HopeSF (Potrero + Sunnydale) | B22: 2720 | C22: BRIDGE Housing; Mercy Housing/Related
A23: Potrero Power Plant / Power Station | B23: 2228 | C23: Associate Capital
A24: Pier 70 | B24: 1634 | C24: Brookfield Properties
A25: India Basin | B25: 1575 | C25: BUILD Inc
A26: Mission Rock | B26: 1409 | C26: SF Giants / Tishman Speyer
A27: Schlage Lock | B27: 1123 | C27: (not assigned)
A28: 3333 California (Laurel Heights) | B28: 744 | C28: Prado Group / SKS Partners
... A30: 5M | B30: 386 | C30: Brookfield Properties
A31: Total | B31: =SUM(B17:B30) -> 40479
A33: Density bonus pipeline (HI 2025 Tables 11–12, Dec 2025): 93 State Density Bonus projects = 17,554 units (4,175 affordable); 11 HOME-SF projects = 422 units (112 affordable).

Sheet Projects
A1: Project ID | B1: Project Name | C1: Project Address | D1: Analysis Neighborhood | E1: Supervisor District | F1: Status (raw, source) | G1: Status (normalized) | H1: Project Type | I1: Tenure | J1: Total Units | K1: Affordable Units | L1: Affordability mix (units @ AMI) | M1: Size Bucket | N1: Developer / Sponsor | O1: Co-developer / Partner | P1: General Contractor | Q1: Architect | R1: Total Project Cost ($) | S1: Equity Partners | T1: Equity $ | U1: Lenders | V1: Loan $ | W1: Est./Actual Completion | X1: Year Completed | Y1: Notes / Milestones | Z1: Source URL
A2: C23-01 | B2: 198 McAllister (UC Law SF student housing) | C2: 198 McAllister St | D2: Tenderloin | E2: 5 | F2: Completed 2023 (HI 2023 A-1) | G2: Complete | H2: Student Housing | I2: Rental | J2: 657 | K2: 0 | M2: =IF(J2="","",IF(J2<=4,"≤4",IF(J2<=10,"5–10",IF(J2<=20,"11–20",IF(J2<=50,"21–50",IF(J2<=250,"51–250","251+")))))) -> 251+ | N2: UC Law SF / Greystar | X2: 2023 | Y2: Authorized Feb 2023; largest 2023 completion | Z2: https://sfplanning.org/sites/default/files/resources/2024-04/2023_Housing_Inventory.pdf
A3: C23-02 | B3: 1011 3rd St (Mission Rock Bldg) | C3: 1011 3rd St | D3: Mission Bay | E3: 6 | F3: Completed 2023 (HI 2023 A-1/A-2) | G3: Complete | H3: Mixed-Use | I3: Rental | J3: 283 | K3: 64 | L3: 64 @ Moderate (80-120% AMI) | M3: =IF(J3="","",IF(J3<=4,"≤4",IF(J3<=10,"5–10",IF(J3<=20,"11–20",IF(J3<=50,"21–50",IF(J3<=250,"51–250","251+")))))) -> 251+ | N3: Mission Rock Partners (SF Giants / Tishman Speyer) | X3: 2023 | Y3: Authorized Feb 2023 | Z3: https://sfplanning.org/sites/default/files/resources/2024-04/2023_Housing_Inventory.pdf
A4: C23-03 | B4: 65 Ocean Ave (Ventana Residences) | C4: 65 Ocean Ave | D4: Outer Mission | E4: 11 | F4: Completed 2023 (HI 2023 A-1/A-2) | G4: Complete | H4: Mixed-Use | I4: Rental | J4: 193 | K4: 48 | L4: 34 @ Low (50-80%); 14 @ Moderate | M4: =IF(J4="","",IF(J4<=4,"≤4",IF(J4<=10,"5–10",IF(J4<=20,"11–20",IF(J4<=50,"21–50",IF(J4<=250,"51–250","251+")))))) -> 51–250 | N4: Greystar | X4: 2023 | Z4: https://sfplanning.org/sites/default/files/resources/2024-04/2023_Housing_Inventory.pdf
A5: C23-04 | B5: 1629 Market St | C5: 1629 Market St | D5: Mission | E5: 6 | F5: Completed 2023 (HI 2023 A-1) | G5: Complete | H5: Mixed-Use | J5: 185 | K5: 0 | M5: =IF(J5="","",IF(J5<=4,"≤4",IF(J5<=10,"5–10",IF(J5<=20,"11–20",IF(J5<=50,"21–50",IF(J5<=250,"51–250","251+")))))) -> 51–250 | X5: 2023 | Z5: https://sfplanning.org/sites/default/files/resources/2024-04/2023_Housing_Inventory.pdf
A6: C23-05 | B6: 52 Kirkwood Ave | C6: 52 Kirkwood Ave | D6: Bayview Hunters Point | E6: 10 | F6: Completed 2023 (HI 2023 A-1) | G6: Complete | H6: New Construction | J6: 77 | K6: 9 | M6: =IF(J6="","",IF(J6<=4,"≤4",IF(J6<=10,"5–10",IF(J6<=20,"11–20",IF(J6<=50,"21–50",IF(J6<=250,"51–250","251+")))))) -> 51–250 | X6: 2023 | Y6: 68 of 77 units completed in 2023 | Z6: https://sfplanning.org/sites/default/files/resources/2024-04/2023_Housing_Inventory.pdf
A7: C23-06 | B7: 2750 19th St | C7: 2750 19th St | D7: Mission | E7: 9 | F7: Completed 2023 (HI 2023 A-1/A-2) | G7: Complete | H7: Mixed-Use | J7: 63 | K7: 11 | L7: 11 @ Low (50-80%) | M7: =IF(J7="","",IF(J7<=4,"≤4",IF(J7<=10,"5–10",IF(J7<=20,"11–20",IF(J7<=50,"21–50",IF(J7<=250,"51–250","251+")))))) -> 51–250 | X7: 2023 | Z7: https://sfplanning.org/sites/default/files/resources/2024-04/2023_Housing_Inventory.pdf
A8: C23-07 | B8: 1570 Pacific Ave | C8: 1570 Pacific Ave | D8: Russian Hill | E8: 3 | F8: Completed 2023 (HI 2023 A-1) | G8: Complete | H8: New Construction | I8: Ownership | J8: 53 | K8: 7 | M8: =IF(J8="","",IF(J8<=4,"≤4",IF(J8<=10,"5–10",IF(J8<=20,"11–20",IF(J8<=50,"21–50",IF(J8<=250,"51–250","251+")))))) -> 51–250 | X8: 2023 | Z8: https://sfplanning.org/sites/default/files/resources/2024-04/2023_Housing_Inventory.pdf
A9: C23-08 | B9: 530 Brannan St | C9: 530 Brannan St | D9: South of Market | E9: 6 | F9: Completed 2023 (HI 2023 A-1) | G9: Complete | H9: New Construction | J9: 42 | K9: 0 | M9: =IF(J9="","",IF(J9<=4,"≤4",IF(J9<=10,"5–10",IF(J9<=20,"11–20",IF(J9<=50,"21–50",IF(J9<=250,"51–250","251+")))))) -> 21–50 | X9: 2023 | Y9: 10 units completed 2023; 32 prior | Z9: https://sfplanning.org/sites/default/files/resources/2024-04/2023_Housing_Inventory.pdf
A10: C23-09 | B10: 2525 Van Ness Ave | C10: 2525 Van Ness Ave | D10: Russian Hill | E10: 2 | F10: Completed 2023 (HI 2023 A-1) | G10: Complete | H10: New Construction | J10: 28 | K10: 0 | M10: =IF(J10="","",IF(J10<=4,"≤4",IF(J10<=10,"5–10",IF(J10<=20,"11–20",IF(J10<=50,"21–50",IF(J10<=250,"51–250","251+")))))) -> 21–50 | X10: 2023 | Z10: https://sfplanning.org/sites/default/files/resources/2024-04/2023_Housing_Inventory.pdf
A11: C23-10 | B11: 603 Tennessee St | C11: 603 Tennessee St | D11: Potrero Hill | E11: 10 | F11: Completed 2023 (HI 2023 A-1) | G11: Complete | H11: New Construction | I11: Rental | J11: 24 | K11: 3 | M11: =IF(J11="","",IF(J11<=4,"≤4",IF(J11<=10,"5–10",IF(J11<=20,"11–20",IF(J11<=50,"21–50",IF(J11<=250,"51–250","251+")))))) -> 21–50 | X11: 2023 | Z11: https://sfplanning.org/sites/default/files/resources/2024-04/2023_Housing_Inventory.pdf
A12: C23-11 | B12: 921 Howard St (100% affordable) | C12: 921 Howard St | D12: South of Market | E12: 6 | F12: Completed 2023 (HI 2023 A-2) | G12: Complete | H12: 100% Affordable | I12: Rental | J12: 203 | K12: 201 | L12: 102 @ Low (50-80%); 99 @ Moderate | M12: =IF(J12="","",IF(J12<=4,"≤4",IF(J12<=10,"5–10",IF(J12<=20,"11–20",IF(J12<=50,"21–50",IF(J12<=250,"51–250","251+")))))) -> 51–250 | Q12: Perry Architects | X12: 2023 | Y12: 195 of 203 units completed in 2023 | Z12: https://sfplanning.org/sites/default/files/resources/2024-04/2023_Housing_Inventory.pdf
A13: C23-12 | B13: 2340 San Jose Ave (Balboa Park Upper Yard) | C13: 2340 San Jose Ave | D13: Outer Mission | E13: 11 | F13: Completed 2023 (HI 2023 A-2) | G13: Complete | H13: 100% Affordable | I13: Rental | J13: 131 | K13: 130 | L13: 88 @ Very Low (<=50%); 24 @ Low; 18 @ Moderate | M13: =IF(J13="","",IF(J13<=4,"≤4",IF(J13<=10,"5–10",IF(J13<=20,"11–20",IF(J13<=50,"21–50",IF(J13<=250,"51–250","251+")))))) -> 51–250 | N13: Related California | O13: Mission Housing Development Corp | X13: 2023 | Z13: https://sfplanning.org/sites/default/files/resources/2024-04/2023_Housing_Inventory.pdf
A14: C23-13 | B14: 440 Geary St | C14: 440 Geary St | D14: Tenderloin | E14: 3 | F14: Completed 2023 (HI 2023 A-2) | G14: Complete | H14: Mixed-Use | J14: 122 | K14: 21 | L14: 21 @ Very Low (<=50%) | M14: =IF(J14="","",IF(J14<=4,"≤4",IF(J14<=10,"5–10",IF(J14<=20,"11–20",IF(J14<=50,"21–50",IF(J14<=250,"51–250","251+")))))) -> 51–250 | X14: 2023 | Z14: https://sfplanning.org/sites/default/files/resources/2024-04/2023_Housing_Inventory.pdf
A15: C23-14 | B15: Treasure Island (1 Avenue of the Palms, 2023 phase) | C15: 1 Avenue of the Palms | D15: Treasure Island | E15: 6 | F15: Completed 2023 (HI 2023 A-2) | G15: Complete | H15: Major Multi-Phase | J15: 105 | K15: 105 | L15: 105 @ Low (50-80%) | M15: =IF(J15="","",IF(J15<=4,"≤4",IF(J15<=10,"5–10",IF(J15<=20,"11–20",IF(J15<=50,"21–50",IF(J15<=250,"51–250","251+")))))) -> 51–250 | N15: Treasure Island Community Development (Wilson Meany / Stockbridge / Lennar) | X15: 2023 | Y15: 96 of 105 completed in 2023 | Z15: https://sfplanning.org/sites/default/files/resources/2024-04/2023_Housing_Inventory.pdf
A16: C23-15 | B16: 363 Noe St | C16: 363 Noe St | D16: Castro/Upper Market | E16: 8 | F16: Completed 2023 (HI 2023 A-2) | G16: Complete | H16: 100% Affordable (acq/rehab) | J16: 43 | K16: 20 | L16: 20 @ Very Low (<=50%) | M16: =IF(J16="","",IF(J16<=4,"≤4",IF(J16<=10,"5–10",IF(J16<=20,"11–20",IF(J16<=50,"21–50",IF(J16<=250,"51–250","251+")))))) -> 21–50 | X16: 2023 | Y16: 21 of 43 completed 2023 | Z16: https://sfplanning.org/sites/default/files/resources/2024-04/2023_Housing_Inventory.pdf
A17: C24-01 | B17: 1070 Bridgeview Way (Mission Rock) | C17: 1070 Bridgeview Way | D17: Mission Bay | E17: 6 | F17: Completed 2024 (HI 2024 A-1/A-2) | G17: Complete | H17: Mixed-Use | I17: Rental | J17: 258 | K17: 59 | L17: 59 @ Moderate (80-120%) | M17: =IF(J17="","",IF(J17<=4,"≤4",IF(J17<=10,"5–10",IF(J17<=20,"11–20",IF(J17<=50,"21–50",IF(J17<=250,"51–250","251+")))))) -> 251+ | N17: Mission Rock Partners (SF Giants / Tishman Speyer) | X17: 2024 | Y17: Authorized Feb 2023 | Z17: https://sfplanning.org/sites/default/files/resources/2025-04/2024_Housing%20Inventory.pdf
A18: C24-02 | B18: Treasure Island: Star View Court + Tidal House (1 Avenue of the Palms) | C18: 1 Avenue of the Palms | D18: Treasure Island | E18: 6 | F18: Completed 2024 (HI 2024 A-1/A-2) | G18: Complete | H18: Major Multi-Phase | I18: Rental | J18: 388 | K18: 138 | L18: 71 @ Very Low; 55 @ Low; 12 @ Moderate | M18: =IF(J18="","",IF(J18<=4,"≤4",IF(J18<=10,"5–10",IF(J18<=20,"11–20",IF(J18<=50,"21–50",IF(J18<=250,"51–250","251+")))))) -> 251+ | N18: Treasure Island Community Development (Wilson Meany / Stockbridge / Lennar) | O18: Star View Court: Mercy Housing CA + Catholic Charities (138 units) | X18: 2024 | Y18: 388 units incl. 250 market-rate + 138 affordable (Star View Court) | Z18: https://sfplanning.org/sites/default/files/resources/2025-04/2024_Housing%20Inventory.pdf
A19: C24-03 | B19: 36 Meadow Dr | C19: 36 Meadow Dr | F19: Completed 2024 (HI 2024 A-1) | G19: Complete | H19: New Construction | J19: 14 | K19: 0 | M19: =IF(J19="","",IF(J19<=4,"≤4",IF(J19<=10,"5–10",IF(J19<=20,"11–20",IF(J19<=50,"21–50",IF(J19<=250,"51–250","251+")))))) -> 11–20 | X19: 2024 | Z19: https://sfplanning.org/sites/default/files/resources/2025-04/2024_Housing%20Inventory.pdf
A20: C24-04 | B20: 400 China Basin St (Mission Bay affordable) | C20: 400 China Basin St | D20: Mission Bay | E20: 6 | F20: Completed 2024 (HI 2024 A-2) | G20: Complete | H20: 100% Affordable | J20: 148 | K20: 148 | L20: 29 @ Low (50-80%); 119 @ Moderate | M20: =IF(J20="","",IF(J20<=4,"≤4",IF(J20<=10,"5–10",IF(J20<=20,"11–20",IF(J20<=50,"21–50",IF(J20<=250,"51–250","251+")))))) -> 51–250 | X20: 2024 | Z20: https://sfplanning.org/sites/default/files/resources/2025-04/2024_Housing%20Inventory.pdf
A21: C24-05 | B21: 4840 Mission St | C21: 4840 Mission St | D21: Outer Mission | E21: 11 | F21: Completed 2024 (HI 2024 A-2) | G21: Complete | H21: 100% Affordable | I21: Rental | J21: 137 | K21: 135 | L21: 98 @ Low (50-80%); 37 @ Moderate | M21: =IF(J21="","",IF(J21<=4,"≤4",IF(J21<=10,"5–10",IF(J21<=20,"11–20",IF(J21<=50,"21–50",IF(J21<=250,"51–250","251+")))))) -> 51–250 | N21: Mission Housing Development Corp | O21: BRIDGE Housing | X21: 2024 | Z21: https://sfplanning.org/sites/default/files/resources/2025-04/2024_Housing%20Inventory.pdf
A22: C24-06 | B22: 1360 43rd Ave (Shirley Chisholm Village, educator housing) | C22: 1360 43rd Ave | D22: Sunset/Parkside | E22: 4 | F22: Completed 2024 (HI 2024 A-2) | G22: Complete | H22: 100% Affordable | I22: Rental | J22: 135 | K22: 134 | L22: 20 @ Very Low; 47 @ Low; 67 @ Moderate | M22: =IF(J22="","",IF(J22<=4,"≤4",IF(J22<=10,"5–10",IF(J22<=20,"11–20",IF(J22<=50,"21–50",IF(J22<=250,"51–250","251+")))))) -> 51–250 | N22: MidPen Housing | O22: SFUSD (site) | Q22: BAR Architects | X22: 2024 | Z22: https://sfplanning.org/sites/default/files/resources/2025-04/2024_Housing%20Inventory.pdf
A23: C24-07 | B23: 600 7th St (Potrero Terrace HOPE SF Block X / 1101 Connecticut) | C23: 600 7th St | D23: Potrero Hill | E23: 10 | F23: Completed 2024 (HI 2024 A-2) | G23: Complete | H23: 100% Affordable | I23: Rental | J23: 221 | K23: 220 | L23: 65 @ Ext. Low (<=30%); 78 @ Very Low; 77 @ Low | M23: =IF(J23="","",IF(J23<=4,"≤4",IF(J23<=10,"5–10",IF(J23<=20,"11–20",IF(J23<=50,"21–50",IF(J23<=250,"51–250","251+")))))) -> 51–250 | N23: BRIDGE Housing | X23: 2024 | Y23: 100 of 221 units completed in 2024 | Z23: https://sfplanning.org/sites/default/files/resources/2025-04/2024_Housing%20Inventory.pdf
A24: C24-08 | B24: 180 Jones St | C24: 180 Jones St | D24: Tenderloin | E24: 5 | F24: Completed 2024 (HI 2024 A-2) | G24: Complete | H24: 100% Affordable | I24: Rental | J24: 70 | K24: 69 | L24: 35 @ Ext. Low; 13 @ Very Low; 21 @ Low | M24: =IF(J24="","",IF(J24<=4,"≤4",IF(J24<=10,"5–10",IF(J24<=20,"11–20",IF(J24<=50,"21–50",IF(J24<=250,"51–250","251+")))))) -> 51–250 | N24: Tenderloin Neighborhood Development Corp (TNDC) | X24: 2024 | Z24: https://sfplanning.org/sites/default/files/resources/2025-04/2024_Housing%20Inventory.pdf
A25: C25-01 | B25: Quincy (555 Bryant St) | C25: 555 Bryant St | D25: South of Market | E25: 6 | F25: Completed 2025 (HI 2025 A-1/A-2) | G25: Complete | H25: Mixed-Use | I25: Rental | J25: 500 | K25: 78 | L25: 46 @ Very Low; 16 @ Low; 16 @ Moderate | M25: =IF(J25="","",IF(J25<=4,"≤4",IF(J25<=10,"5–10",IF(J25<=20,"11–20",IF(J25<=50,"21–50",IF(J25<=250,"51–250","251+")))))) -> 251+ | N25: Strada Investment Group | Q25: Solomon Cordwell Buenz (SCB) | X25: 2025 | Y25: Opened May 2025; 16 stories; land bought for $44.9M; CoStar 2026 Impact Award - fastest lease-up since 2013 | Z25: https://www.costar.com/article/147377327
A26: C25-02 | B26: 55 Bruton St | C26: 55 Bruton St | D26: Visitacion Valley | E26: 10 | F26: Completed 2025 (HI 2025 A-1) | G26: Complete | H26: New Construction | J26: 178 | K26: 9 | M26: =IF(J26="","",IF(J26<=4,"≤4",IF(J26<=10,"5–10",IF(J26<=20,"11–20",IF(J26<=50,"21–50",IF(J26<=250,"51–250","251+")))))) -> 51–250 | X26: 2025 | Z26: https://sfplanning.org/sites/default/files/resources/2026-04/2025_Housing_Inventory.pdf
A27: C25-03 | B27: 377 6th St | C27: 377 6th St | D27: South of Market | E27: 6 | F27: Completed 2025 (HI 2025 A-1/A-2) | G27: Complete | H27: New Construction | I27: Ownership | J27: 90 | K27: 12 | L27: 12 @ Low (50-80%) | M27: =IF(J27="","",IF(J27<=4,"≤4",IF(J27<=10,"5–10",IF(J27<=20,"11–20",IF(J27<=50,"21–50",IF(J27<=250,"51–250","251+")))))) -> 51–250 | X27: 2025 | Z27: https://sfplanning.org/sites/default/files/resources/2026-04/2025_Housing_Inventory.pdf
A28: C25-04 | B28: 4742 Mission St | C28: 4742 Mission St | D28: Outer Mission | E28: 11 | F28: Completed 2025 (HI 2025 A-1/A-2) | G28: Complete | H28: Mixed-Use | I28: Rental | J28: 46 | K28: 12 | L28: 9 @ Low; 3 @ Moderate | M28: =IF(J28="","",IF(J28<=4,"≤4",IF(J28<=10,"5–10",IF(J28<=20,"11–20",IF(J28<=50,"21–50",IF(J28<=250,"51–250","251+")))))) -> 21–50 | X28: 2025 | Z28: https://sfplanning.org/sites/default/files/resources/2026-04/2025_Housing_Inventory.pdf
A29: C25-05 | B29: 915 North Point St | C29: 915 North Point St | D29: Russian Hill | E29: 2 | F29: Completed 2025 (HI 2025 A-1) | G29: Complete | H29: New Construction | J29: 35 | K29: 0 | M29: =IF(J29="","",IF(J29<=4,"≤4",IF(J29<=10,"5–10",IF(J29<=20,"11–20",IF(J29<=50,"21–50",IF(J29<=250,"51–250","251+")))))) -> 21–50 | X29: 2025 | Y29: Authorized Nov 2023 | Z29: https://sfplanning.org/sites/default/files/resources/2026-04/2025_Housing_Inventory.pdf
A30: C25-06 | B30: 2100 Mission St | C30: 2100 Mission St | D30: Mission | E30: 9 | F30: Completed 2025 (HI 2025 A-1) | G30: Complete | H30: Mixed-Use | J30: 28 | K30: 4 | M30: =IF(J30="","",IF(J30<=4,"≤4",IF(J30<=10,"5–10",IF(J30<=20,"11–20",IF(J30<=50,"21–50",IF(J30<=250,"51–250","251+")))))) -> 21–50 | X30: 2025 | Z30: https://sfplanning.org/sites/default/files/resources/2026-04/2025_Housing_Inventory.pdf
A31: C25-07 | B31: 693 Sutter St | C31: 693 Sutter St | D31: Nob Hill | E31: 3 | F31: Completed 2025 (HI 2025 A-1) | G31: Complete | H31: New Construction | J31: 17 | K31: 0 | M31: =IF(J31="","",IF(J31<=4,"≤4",IF(J31<=10,"5–10",IF(J31<=20,"11–20",IF(J31<=50,"21–50",IF(J31<=250,"51–250","251+")))))) -> 11–20 | X31: 2025 | Z31: https://sfplanning.org/sites/default/files/resources/2026-04/2025_Housing_Inventory.pdf
A32: C25-08 | B32: 986 South Van Ness Ave | C32: 986 South Van Ness Ave | D32: Mission | E32: 9 | F32: Completed 2025 (HI 2025 A-1) | G32: Complete | H32: New Construction | J32: 15 | K32: 2 | M32: =IF(J32="","",IF(J32<=4,"≤4",IF(J32<=10,"5–10",IF(J32<=20,"11–20",IF(J32<=50,"21–50",IF(J32<=250,"51–250","251+")))))) -> 11–20 | X32: 2025 | Z32: https://sfplanning.org/sites/default/files/resources/2026-04/2025_Housing_Inventory.pdf
A33: C25-09 | B33: Sunnydale HOPE SF Block 3B (1501 Sunnydale Ave) | C33: 1501 Sunnydale Ave | D33: Visitacion Valley | E33: 10 | F33: Completed 2025 (HI 2025 A-2) | G33: Complete | H33: 100% Affordable (HOPE SF) | I33: Rental | J33: 170 | K33: 168 | L33: 127 @ Very Low (<=50%); 41 @ Low | M33: =IF(J33="","",IF(J33<=4,"≤4",IF(J33<=10,"5–10",IF(J33<=20,"11–20",IF(J33<=50,"21–50",IF(J33<=250,"51–250","251+")))))) -> 51–250 | N33: Mercy Housing California | O33: Related California | X33: 2025 | Y33: Authorized Mar 2023 | Z33: https://sfplanning.org/sites/default/files/resources/2026-04/2025_Housing_Inventory.pdf
A34: C25-10 | B34: 730 Stanyan St | C34: 730 Stanyan St | D34: Haight Ashbury | E34: 5 | F34: Completed 2025 (HI 2025 A-2) | G34: Complete | H34: 100% Affordable | I34: Rental | J34: 160 | K34: 159 | L34: 56 @ Ext. Low; 36 @ Very Low; 67 @ Low (25-80% AMI); 20 TAY units; 32 PBV | M34: =IF(J34="","",IF(J34<=4,"≤4",IF(J34<=10,"5–10",IF(J34<=20,"11–20",IF(J34<=50,"21–50",IF(J34<=250,"51–250","251+")))))) -> 51–250 | N34: Tenderloin Neighborhood Development Corp (TNDC) | O34: Chinatown Community Development Center (CCDC) | P34: Cahill Contractors / Hercules JV | Q34: OMA (NYC) + Y.A. Studio (SF) | R34: 155000000 | S34: 4% LIHTC equity (investor not disclosed) | U34: Bank of America (construction); MOHCD (2019 Affordable Housing GO Bond); tax-exempt bonds | W34: Fall 2025 | X34: 2025 | Y34: Approved Jan 2024; authorized Jun 2023; Type I; Clark Pacific Infinite Facade GFRC panels; $153.2M per SF.gov, $155M per CCDC | Z34: https://www.chinatowncdc.org/our-housing/in-development
A35: C25-11 | B35: Potrero Terrace Block B (1801 25th St) | C35: 1801 25th St | D35: Potrero Hill | E35: 10 | F35: Completed 2025 (HI 2025 A-2) | G35: Complete | H35: 100% Affordable (HOPE SF) | I35: Rental | J35: 157 | K35: 157 | L35: 49 @ Ext. Low; 72 @ Very Low; 36 @ Low | M35: =IF(J35="","",IF(J35<=4,"≤4",IF(J35<=10,"5–10",IF(J35<=20,"11–20",IF(J35<=50,"21–50",IF(J35<=250,"51–250","251+")))))) -> 51–250 | N35: BRIDGE Housing | Q35: HKIT Architects | X35: 2025 | Y35: Cover project of 2025 Housing Inventory | Z35: https://sfplanning.org/sites/default/files/resources/2026-04/2025_Housing_Inventory.pdf
A36: C25-12 | B36: Transbay Block 2 West - Senior (200 Folsom St) | C36: 200 Folsom St | D36: Financial District/South Beach | E36: 6 | F36: Completed 2025 (HI 2025 A-2) | G36: Complete | H36: 100% Affordable (senior) | I36: Rental | J36: 151 | K36: 150 | L36: 24 @ Ext. Low; 66 @ Very Low; 60 @ Low (15-50% AMI); 30 PSH units | M36: =IF(J36="","",IF(J36<=4,"≤4",IF(J36<=10,"5–10",IF(J36<=20,"11–20",IF(J36<=50,"21–50",IF(J36<=250,"51–250","251+")))))) -> 51–250 | N36: Chinatown Community Development Center (CCDC) | Q36: (see TB2 East for block team) | S36: 4% LIHTC: $6,235,472/yr federal credits (CTCAC CA-23-567); CHPC investor consultant | U36: City & County of SF (bond issuer, OCII/MOHCD); HUD PBV (60 units); LOSP $11.8M/15 yrs | W36: Feb 2026 (MOHCD est.); HI counts 2025 TCO | X36: 2025 | Y36: 9-story Type I; groundbreaking 2023; FCD Mar 2024 | Z36: https://www.treasurer.ca.gov/ctcac/meeting/2023/0823/staff/CA-23-567.pdf
A37: C25-13 | B37: 1633 Valencia St (senior PSH) | C37: 1633 Valencia St | D37: Bernal Heights | E37: 9 | F37: Completed 2025 (HI 2025 A-2) | G37: Complete | H37: 100% Affordable (senior PSH) | I37: Rental | J37: 146 | K37: 145 | L37: 145 @ Very Low (15-50% AMI) | M37: =IF(J37="","",IF(J37<=4,"≤4",IF(J37<=10,"5–10",IF(J37<=20,"11–20",IF(J37<=50,"21–50",IF(J37<=250,"51–250","251+")))))) -> 51–250 | N37: Mercy Housing California | O37: Sequoia Living (site partner); HSH | Q37: David Baker Architects | R37: 84600000 | S37: Bay Area Housing Innovation Fund ($50M fund: SF Housing Accelerator Fund, Apple, Destination: Home, Sobrato Philanthropies) | U37: MOHCD permanent up to $41.0M (incl. $2M AHP bridge); LOSP 20-yr $80.8M | W37: Dec 2025 | X37: 2025 | Y37: Approved Feb 2023 (SB 35); groundbreaking Jul 2024; built in ~17 months; sub-$600k/unit; 'Chevrolet Six' ghost sign site | Z37: https://www.sf.gov/news/mayor-london-breed-celebrates-groundbreaking-new-senior-housing-development-mission
A38: C25-14 | B38: 1151 Fairfax Ave (Hunters View) | C38: 1151 Fairfax Ave | D38: Bayview Hunters Point | E38: 10 | F38: Completed 2025 (HI 2025 A-2) | G38: Complete | H38: 100% Affordable (HOPE SF) | J38: 118 | K38: 101 | L38: 14 @ Very Low; 87 @ Low | M38: =IF(J38="","",IF(J38<=4,"≤4",IF(J38<=10,"5–10",IF(J38<=20,"11–20",IF(J38<=50,"21–50",IF(J38<=250,"51–250","251+")))))) -> 51–250 | N38: John Stewart Company | X38: 2025 | Y38: Authorized Jun 2023 | Z38: https://sfplanning.org/sites/default/files/resources/2026-04/2025_Housing_Inventory.pdf
A39: C25-15 | B39: 240 Van Ness Ave | C39: 240 Van Ness Ave | D39: Hayes Valley | E39: 5 | F39: Completed 2025 (HI 2025 A-2) | G39: Complete | H39: 100% Affordable | I39: Rental | J39: 112 | K39: 110 | L39: 30 @ Very Low; 80 @ Low | M39: =IF(J39="","",IF(J39<=4,"≤4",IF(J39<=10,"5–10",IF(J39<=20,"11–20",IF(J39<=50,"21–50",IF(J39<=250,"51–250","251+")))))) -> 51–250 | X39: 2025 | Y39: Authorized Feb 2023 | Z39: https://sfplanning.org/sites/default/files/resources/2026-04/2025_Housing_Inventory.pdf
A40: C25-16 | B40: 1212 Maryland St | C40: 1212 Maryland St | D40: Potrero Hill | E40: 10 | F40: Completed 2025 (HI 2025 A-2) | G40: Complete | H40: 100% Affordable | I40: Rental | J40: 105 | K40: 104 | L40: 21 @ Very Low; 62 @ Low; 21 @ Moderate | M40: =IF(J40="","",IF(J40<=4,"≤4",IF(J40<=10,"5–10",IF(J40<=20,"11–20",IF(J40<=50,"21–50",IF(J40<=250,"51–250","251+")))))) -> 51–250 | X40: 2025 | Z40: https://sfplanning.org/sites/default/files/resources/2026-04/2025_Housing_Inventory.pdf
...

Sheet Sources
A1: Sources
A2: ID | B2: Source | C2: Publisher | D2: URL | E2: Retrieved | F2: Covers | G2: Refresh cadence
A3: S1 | B3: 2025 San Francisco Housing Inventory (56th ed.) | C3: SF Planning | D3: https://sfplanning.org/sites/default/files/resources/2026-04/2025_Housing_Inventory.pdf | E3: 2026-09-09 | F3: Stock, trends, 2025 completions/approvals/authorizations, affordability | G3: Annual, ~April 1
A4: S2 | B4: 2024 San Francisco Housing Inventory | C4: SF Planning | D4: https://sfplanning.org/sites/default/files/resources/2025-04/2024_Housing%20Inventory.pdf | E4: 2026-09-09 | F4: 2024 completions & approvals | G4: Superseded annually
A5: S3 | B5: 2023 San Francisco Housing Inventory | C5: SF Planning | D5: https://sfplanning.org/sites/default/files/resources/2024-04/2023_Housing_Inventory.pdf | E5: 2026-09-09 | F5: 2023 completions, approvals, authorizations | G5: Superseded annually
A6: S4 | B6: Housing Inventory landing page | C6: SF Planning | D6: https://sfplanning.org/project/housing-inventory | E6: 2026-09-09 | F6: Latest report link | G6: Annual
A7: S5 | B7: Pipeline Report 2026 Q2 (page + PDF) | C7: SF Planning | D7: https://sfplanning.org/project/pipeline-report | E7: 2026-09-09 | F7: Stage totals, affordable units, multi-phase list | G7: Quarterly (~2 months after quarter end)
A8: S6 | B8: San Francisco Development Pipeline (dataset 6jgi-cpb4, 2026 Q2) | C8: DataSF | D8: https://data.sf.gov/d/6jgi-cpb4 | E8: 2026-09-09 | F8: Row-level pipeline incl. sponsor, contact, BMR by AMI, neighborhood, SD; CSV export: https://data.sf.gov/api/v3/views/6jgi-cpb4/export.csv?accessType=DOWNLOAD | G8: Quarterly
A9: S7 | B9: MOHCD/OCII Affordable Housing Pipeline (dataset aaxw-2cb8) | C9: DataSF / MOHCD | D9: https://data.sfgov.org/Housing-and-Buildings/Affordable-Housing-Pipeline/aaxw-2cb8 | E9: 2026-09-09 | F9: Affordable + inclusionary projects: sponsor, status, AMI mix, schedule; CSV: https://data.sfgov.org/api/views/aaxw-2cb8/rows.csv?accessType=DOWNLOAD | G9: Periodic (last modified 2026-02-05)
A10: S8 | B10: San Francisco Housing Dashboard | C10: SF Planning | D10: https://sfplanning.org/san-francisco-housing-dashboard | E10: 2026-09-09 | F10: Completed units since 2005; active pipeline by geography/affordability | G10: Continuous
A11: S9 | B11: Dwelling Unit Completion Counts by Building Permit (j67f-aayr) | C11: DataSF | D11: https://data.sfgov.org/Housing-and-Buildings/Dwelling-Unit-Completion-Counts-by-Building-Permit/j67f-aayr | E11: 2026-09-09 | F11: Monthly completions (use for 2026 YTD) | G11: Monthly
A12: S10 | B12: 'SF Has Built Only 400 Homes This Year...' | C12: The Frisc (A. Brinklow) | D12: https://thefrisc.com/sf-has-built-only-400-homes-this-year-tens-of-thousands-more-are-waiting/ | E12: 2026-09-09 | F12: 2026 H1 completions (405), UC trend, MOHCD 2,000 affordable UC | G12: n/a
A13: S11 | B13: 'More homes are entering S.F.'s pipeline...' | C13: SF Chronicle | D13: https://www.sfchronicle.com/realestate/article/sf-homes-built-22208676.php | E13: 2026-09-09 | F13: 2025 filings context (88 Bluxome, Marina Safeway, 10 SVN) | G13: n/a
... A23: S21 | B23: Chinatown CDC — In Development (730 Stanyan) | C23: CCDC | D23: https://www.chinatowncdc.org/our-housing/in-development | E23: 2026-09-09 | F23: GC, architect, TDC | G23: Continuous

Sheet How_to_update
A1: How to update this workbook
A3: Step | B3: What | C3: Where | D3: How | E3: Cadence
A4: 1 | B4: Refresh citywide stock, trend, affordable tables (Stock A, Trend) | C4: Housing Inventory (S1/S4) | D4: Download the new PDF each April. Copy Tables 1, 2, 3, 4, 13, 23, 24, 27, 28 into the Stock/Trend tabs. Note: prior years get restated; overwrite the whole series from the newest report. | E4: Annual (April)
A5: 2 | B5: Add completed projects for the new year | C5: Housing Inventory Appendix A-1 (market-rate ≥10 units) and A-2 (affordable ≥20 units) | D5: Add one Projects row per project with Status = Complete, Year Completed = report year, Source URL = the PDF. Merge with existing rows if the project was already tracked (change status, add milestone to Notes). | E5: Annual (April)
A6: 3 | B6: Refresh pipeline stage totals and multi-phase list (Pipeline_Q2_2026 tab; rename tab) | C6: Pipeline Report page (S5) | D6: Copy the summary breakdown and the 14-project list from the quarterly page/PDF. Update Summary section A rows 14–23. | E6: Quarterly
A7: 4 | B7: Pull row-level pipeline for status changes and small projects | C7: DataSF 6jgi-cpb4 CSV (S6) | D7: Download CSV; filter 'net pipeline units' > 0; columns: NAMEADDR, current status, net pipeline units, pipeline affordable units, bmr units by AMI, SPONSOR, NHOOD41, SD22. Map 'current status' → normalized: Construction→Under Construction; BP BP Issued→Permitted; BP Approved/BP Filed/PL Approved→Approved; PL Filed→Under Review. Append rows not already in Projects (match on address). | E7: Quarterly
A8: 5 | B8: Refresh affordable project detail (sponsor, AMI mix, schedule) | C8: MOHCD Affordable Housing Pipeline CSV (S7) | D8: Download CSV; key on Project ID. Update Status (raw), construction status (0–5), est. completion, AMI columns → rewrite 'Affordability mix' cell as 'n @ x% AMI; ...'. | E8: When modified (check 'Last Updated' on dataset page)
A9: 6 | B9: 2026 YTD completions | C9: Housing Dashboard (S8) or DataSF j67f-aayr (S9) | D9: Sum completed units for the current year; list projects ≥10 units; set Year Completed = 2026. | E9: Monthly
A10: 7 | B10: Capital stack for large projects | C10: CTCAC/CDLAC staff reports (S14), MOHCD Loan Committee (S15), CalHFA (S16), SF YIMBY / Chronicle / Business Times (S17) | D10: Search '<address> CTCAC staff report' for LIHTC/bond/investor; '<address> loan committee' for city loans and TDC; '<address> sfyimby' for GC/architect. Fill Total Project Cost, Equity Partners, Equity $, Lenders, Loan $. Leave blank if not found. | E10: Per project, as milestones occur
A11: 8 | B11: Tenure, vacancy, age of stock (Stock B) | C11: data.census.gov table DP04, ACS 1-year, San Francisco County | D11: Replace values; keep the HUD CMAR row until a newer CMAR is issued. | E11: Annual (Sept)
A12: 9 | B12: Check Summary formulas | C12: Summary tab | D12: Formulas are whole-column COUNTIFS/SUMIFS on Projects — no range edits needed when adding rows. Keep normalized status spellings exactly as listed in README. | E12: After every edit
